fill ~10 ~ ~10 ~-10 ~10 ~-10 air
fill ~10 ~-1 ~10 ~-10 ~-1 ~-10 grass
fill ~4 ~-1 ~4 ~-4 ~-1 ~-4 planks 1
fill ~ ~-1 ~ ~ ~-1 ~ stonebrick 3
fill ~5 ~4 ~4 ~5 ~ ~-4 minecraft:cobblestone
fill ~-5 ~4 ~-4 ~-5 ~ ~4 minecraft:cobblestone
fill ~4 ~4 ~5 ~-4 ~ ~5 minecraft:cobblestone
fill ~4 ~4 ~-5 ~-4 ~ ~-5 minecraft:cobblestone
fill ~-5 ~ ~5 ~-5 ~ ~5 minecraft:stonebrick 3
fill ~5 ~ ~-5 ~5 ~ ~-5 minecraft:stonebrick 3
fill ~-5 ~ ~-5 ~-5 ~ ~-5 minecraft:stonebrick 3
fill ~5 ~ ~5 ~5 ~ ~5 minecraft:stonebrick 3
fill ~-5 ~1 ~5 ~-5 ~4 ~5 log 1
fill ~5 ~1 ~-5 ~5 ~4 ~-5 log 1
fill ~-5 ~1 ~-5 ~-5 ~4 ~-5 log 1
fill ~5 ~1 ~5 ~5 ~4 ~5 log 1
fill ~5 ~5 ~5 ~-5 ~5 ~-5 stone_slab
fill ~ ~ ~ ~ ~ ~ torch
fill ~4 ~ ~4 ~4 ~4 ~4 minecraft:ladder
fill ~4 ~5 ~4 ~4 ~5 ~4 air
fill ~ ~ ~5 ~ ~1 ~5 air
fill ~ ~ ~5 ~ ~ ~5 acacia_fence_gate
fill ~4 ~2 ~-4 ~3 ~ ~-4 minecraft:chest
fill ~-4 ~2 ~-4 ~-3 ~ ~-4 minecraft:chest
fill ~-1 ~2 ~-4 ~-2 ~ ~-4 minecraft:trapped_chest
fill ~2 ~2 ~-4 ~1 ~ ~-4 minecraft:trapped_chest
fill ~ ~ ~-4 ~ ~ ~-4 minecraft:crafting_table
fill ~ ~1 ~-4 ~ ~1 ~-4 minecraft:furnace
fill ~ ~2 ~-4 ~ ~2 ~-4 minecraft:redstone_lamp
fill ~ ~3 ~-4 ~ ~3 ~-4 minecraft:daylight_detector_inverted

tp @s ~ 255 ~ 
kill @s

